Workbook
Name CD: #REF!
Name PRACTICAS: #REF!

Sheet TODOS
A1: nOrden | B1: dFecha | C1: sPaciente | D1: nEdad | E1: sSexo | F1: sEntidad | G1: sNroAfiliado | H1: sBono | I1: sEstado | J1: sTipoPaciente | K1: sSubPlan | L1: sPlan | M1: sCliente | N1: sServicio | O1: sEmpresa | P1: sFilial | Q1: lGuardia | R1: sClase | S1: sPrestacion | T1: sNombrePrestacion | U1: sRegion | V1: nCantidad | W1: sProfesionalDeriv | X1: sProfesionalControlador | Y1: sProfesionalEjec | Z1: nHonorarios | AA1: nGastos | AB1: nDrogas | AC1: nCopago | AD1: sSet | AE1: sAltaUsuario | AF1: sObsEstado | AG1: nSaldo | AH1: sHora | AI1: dFechaEntrega
A2: 995667 | B2: 46143 | C2: PEREZ, EULALIA | D2: 86 | E2: F | F2: PAMI INT CC | G2: 150357314001100 | I2: Lista para Facturar | J2: Exento | K2: UNICO | L2: 1 | N2: RADIOLOGIA | O2: DIAGNOSR | P2: CLINIC - CLINICA CIUDAD | Q2: NO | R2: NNM | S2: 340301 | T2: RX DE TORAX | U2: SIN REGION | V2: 1 | W2: VILLARROEL, OSCAR | X2: 0 | Y2: VARELA, JULIO | Z2: 0 | AA2: 0 | AB2: 0 | AC2: 0 | AD2: S/S | AE2: PMARTIN | AF2: Proceso Auto: Recalculo Orden | AG2: 0 | AH2: 0.0013888889 | AI2: 46147
A3: 995668 | B3: 46143 | C3: SALAS, ALEXANDER | D3: 15 | E3: M | F3: H REGIONAL MG | G3: 50513771 | I3: Lista para Facturar | J3: Exento | K3: UNICO | L3: 1 | N3: TOMOGRAFIA | O3: DIAGNOSR | P3: MALARG - MALARGUE | Q3: NO | R3: NNM | S3: 922026 | T3: TOMOGRAFIA COMPUTADA MULTICORT | U3: SIN REGION | V3: 2 | W3: ARANCIBIA, FERNANDO | X3: 0 | Y3: ASIGNADO, POR RIS | Z3: 0 | AA3: 0 | AB3: 0 | AC3: 0 | AD3: S/S | AE3: VJAQUE | AG3: 0 | AH3: 0.86527778 | AI3: 46147
A4: 995669 | B4: 46144 | C4: NUÑEZ, ELIDE | D4: 85 | E4: F | F4: PAMI AMB CC | G4: 150179740308/00 | I4: Lista para Facturar | J4: Exento | K4: UNICO | L4: 1 | N4: TOMOGRAFIA | O4: DIAGNOSR | P4: DIAGNOSR - CENTRO DEL DIAGNOSTICO | Q4: NO | R4: NNM | S4: 341001 | T4: TOMOGRAFIA COMPUTADA CEREBRAL | U4: SIN REGION | V4: 1 | W4: BARCUDI, DARIO | X4: 0 | Y4: ASIGNADO, POR RIS | Z4: 0 | AA4: 0 | AB4: 0 | AC4: 0 | AD4: S/S | AE4: ELUCERO | AG4: 0 | AH4: 0.34097222 | AI4: 46148
A5: 995670 | B5: 46144 | C5: OLANO, JULIO ROBERTO | D5: 70 | E5: M | F5: PAMI AMB CC | G5: 150086028908/00 | I5: Lista para Facturar | J5: Exento | K5: UNICO | L5: 1 | N5: RADIOLOGIA | O5: DIAGNOSR | P5: DIAGNOSR - CENTRO DEL DIAGNOSTICO | Q5: NO | R5: NNM | S5: 340222 | T5: ESPINOGRAMA | U5: SIN REGION | V5: 1 | W5: PEREZ, JOSE LUIS | X5: 0 | Y5: VARELA, JULIO | Z5: 0 | AA5: 0 | AB5: 0 | AC5: 0 | AD5: S/S | AE5: ELUCERO | AG5: 0 | AH5: 0.34652778 | AI5: 46148
A6: 995671 | B6: 46144 | C6: LOPEZ, MARIA ESTHER | D6: 64 | E6: F | F6: PAMI AMB CC | G6: 155938567106/00 | I6: Lista para Facturar | J6: Exento | K6: UNICO | L6: 1 | N6: RADIOLOGIA | O6: DIAGNOSR | P6: DIAGNOSR - CENTRO DEL DIAGNOSTICO | Q6: NO | R6: NNM | S6: 340201 | T6: RX CRANEO CARA SENOS PAR. 1EXP | U6: SIN REGION | V6: 1 | W6: PEREZ, JOSE LUIS | X6: 0 | Y6: VARELA, JULIO | Z6: 0 | AA6: 0 | AB6: 0 | AC6: 0 | AD6: S/S | AE6: ELUCERO | AG6: 0 | AH6: 0.35069444 | AI6: 46148
A7: 995671 | B7: 46144 | C7: LOPEZ, MARIA ESTHER | D7: 64 | E7: F | F7: PAMI AMB CC | G7: 155938567106/00 | I7: Lista para Facturar | J7: Exento | K7: UNICO | L7: 1 | N7: RADIOLOGIA | O7: DIAGNOSR | P7: DIAGNOSR - CENTRO DEL DIAGNOSTICO | Q7: NO | R7: NNM | S7: 340202 | T7: RX CRANEO CARA SENOS PAR.SUBS | U7: SIN REGION | V7: 1 | W7: PEREZ, JOSE LUIS | X7: 0 | Y7: VARELA, JULIO | Z7: 0 | AA7: 0 | AB7: 0 | AC7: 0 | AD7: S/S | AE7: ELUCERO | AG7: 0 | AH7: 0.35069444 | AI7: 46148
A8: 995672 | B8: 46144 | C8: SAVARINO RUSSO, MARTIN | D8: 23 | E8: M | F8: SANCOR SALUD | G8: 870049/02 | I8: Lista para Facturar | J8: Exento | K8: CMSR CD RX-TAC 61037/0 | L8: 1 | N8: RESONANCIA | O8: DIAGNOSR | P8: DIAGNOSR - CENTRO DEL DIAGNOSTICO | Q8: NO | R8: NNM | S8: 460275 | T8: RMI-AC RODILLA | U8: SIN REGION | V8: 1 | W8: CAMILLETTI, MARIANO | X8: 0 | Y8: ASIGNADO, POR RIS | Z8: 0 | AA8: 0 | AB8: 0 | AC8: 0 | AD8: S/S | AE8: ELUCERO | AG8: 0 | AH8: 0.35277778 | AI8: 46148
A9: 995673 | B9: 46144 | C9: MONTAÑA, MARCOS RAFAEL | D9: 69 | E9: M | F9: PAMI AMB CC | G9: 465017853704/00 | I9: Lista para Facturar | J9: Exento | K9: UNICO | L9: 1 | N9: RADIOLOGIA | O9: DIAGNOSR | P9: DIAGNOSR - CENTRO DEL DIAGNOSTICO | Q9: NO | R9: NNM | S9: 340222 | T9: ESPINOGRAMA | U9: SIN REGION | V9: 1 | W9: OVIEDO, JORGE EDUARDO | X9: 0 | Y9: VARELA, JULIO | Z9: 0 | AA9: 0 | AB9: 0 | AC9: 0 | AD9: S/S | AE9: ELUCERO | AG9: 0 | AH9: 0.35486111 | AI9: 46148
A10: 995674 | B10: 46144 | C10: SOSA, SILVIA | D10: 51 | E10: F | F10: OSPIA | G10: 27240990364 | I10: Lista para Facturar | J10: Exento | K10: CMSR CD RX-TAC 61037/0 | L10: 1 | N10: MAMOGRAFIA | O10: DIAGNOSR | P10: DIAGNOSR - CENTRO DEL DIAGNOSTICO | Q10: NO | R10: NNM | S10: 340602 | T10: MAMOGRAFIA CON PROY.AXILAR | U10: SIN REGION | V10: 2 | W10: ZUÑIGA, IRMA | X10: 0 | Y10: PLA, CAMILA | Z10: 10 | AA10: 0 | AB10: 0 | AC10: 10 | AD10: S/S | AE10: ELUCERO | AG10: 20 | AH10: 0.35625 | AI10: 46148
A11: 995674 | B11: 46144 | C11: SOSA, SILVIA | D11: 51 | E11: F | F11: OSPIA | G11: 27240990364 | I11: Lista para Facturar | J11: Exento | K11: CMSR CD RX-TAC 61037/0 | L11: 1 | N11: MAMOGRAFIA | O11: DIAGNOSR | P11: DIAGNOSR - CENTRO DEL DIAGNOSTICO | Q11: NO | R11: NNM | S11: 340601 | T11: MAMOGRAFIA (SENOGRAFIA) | U11: SIN REGION | V11: 2 | W11: ZUÑIGA, IRMA | X11: 0 | Y11: PLA, CAMILA | Z11: 10 | AA11: 0 | AB11: 0 | AC11: 10 | AD11: S/S | AE11: ELUCERO | AG11: 20 | AH11: 0.35625 | AI11: 46148
A12: 995675 | B12: 46144 | C12: IZUEL, MARIA TERESA | D12: 71 | E12: M | F12: PAMI AMB CC | G12: 150653937803/00 | I12: Lista para Facturar | J12: Exento | K12: IMAGEN SALUD | L12: 2 | N12: DENSITOMETRIA | O12: DIAGNOSR | P12: DIAGNOSR - CENTRO DEL DIAGNOSTICO | Q12: NO | R12: NNM | S12: 341202 | T12: DENSITOMETRIA OSEA DOS O MAS R | U12: SIN REGION | V12: 1 | W12: SANZ, CARLOS | X12: 0 | Y12: OBLITAS, ROCIO | Z12: 0 | AA12: 0 | AB12: 0 | AC12: 0 | AD12: S/S | AE12: ESLUCERO | AG12: 0 | AH12: 0.35625 | AI12: 46148
A13: 995676 | B13: 46144 | C13: FERNANDEZ, ELENA | D13: 80 | E13: F | F13: PAMI AMB CC | G13: 150290982704/00 | I13: Lista para Facturar | J13: Exento | K13: UNICO | L13: 1 | N13: RADIOLOGIA | O13: DIAGNOSR | P13: DIAGNOSR - CENTRO DEL DIAGNOSTICO | Q13: NO | R13: NNM | S13: 340213 | T13: RX CODO MANO PIE 2 X/PLACA 1EX | U13: SIN REGION | V13: 2 | W13: SOSA AVILA, DIEGO | X13: 0 | Y13: VARELA, JULIO | Z13: 0 | AA13: 0 | AB13: 0 | AC13: 0 | AD13: S/S | AE13: ELUCERO | AG13: 0 | AH13: 0.35833333 | AI13: 46148
A14: 995677 | B14: 46144 | C14: ARGUELLO, ELBA NELIDA | D14: 67 | E14: F | F14: PAMI AMB CC | G14: 140922868908/00 | I14: Lista para Facturar | J14: Exento | K14: IMAGEN SALUD | L14: 2 | N14: DENSITOMETRIA | O14: DIAGNOSR | P14: DIAGNOSR - CENTRO DEL DIAGNOSTICO | Q14: NO | R14: NNM | S14: 341202 | T14: DENSITOMETRIA OSEA DOS O MAS R | U14: SIN REGION | V14: 1 | W14: ROLDAN, BRIAN | X14: 0 | Y14: OBLITAS, ROCIO | Z14: 0 | AA14: 0 | AB14: 0 | AC14: 0 | AD14: S/S | AE14: ESLUCERO | AG14: 0 | AH14: 0.35833333 | AI14: 46148
A15: 995678 | B15: 46144 | C15: PONS, MERCEDES DEL VALLE | D15: 76 | E15: F | F15: PAMI AMB CC | G15: 150578942600/00 | I15: Lista para Facturar | J15: Exento | K15: IMAGEN SALUD | L15: 2 | N15: DENSITOMETRIA | O15: DIAGNOSR | P15: DIAGNOSR - CENTRO DEL DIAGNOSTICO | Q15: NO | R15: NNM | S15: 341202 | T15: DENSITOMETRIA OSEA DOS O MAS R | U15: SIN REGION | V15: 1 | W15: CUELLO, ISIDRO | X15: 0 | Y15: OBLITAS, ROCIO | Z15: 0 | AA15: 0 | AB15: 0 | AC15: 0 | AD15: S/S | AE15: ELUCERO | AG15: 0 | AH15: 0.36041667 | AI15: 46148
A16: 995679 | B16: 46144 | C16: MANSILLA, GREGORIA | D16: 81 | E16: F | F16: PAMI AMB CC | G16: 150145891701/00 | I16: Lista para Facturar | J16: Exento | K16: IMAGEN SALUD | L16: 2 | N16: DENSITOMETRIA | O16: DIAGNOSR | P16: DIAGNOSR - CENTRO DEL DIAGNOSTICO | Q16: NO | R16: NNM | S16: 341201 | T16: DENSITOMETRIA OSEA | U16: SIN REGION | V16: 1 | W16: SEPUR, PEDRO MARTIN | X16: 0 | Y16: OBLITAS, ROCIO | Z16: 0 | AA16: 0 | AB16: 0 | AC16: 0 | AD16: S/S | AE16: ESLUCERO | AG16: 0 | AH16: 0.35972222 | AI16: 46148
A17: 995680 | B17: 46144 | C17: DIAZ, ELBA | D17: 69 | E17: F | F17: PAMI AMB CC | G17: 150078890803/00 | I17: Lista para Facturar | J17: Exento | K17: UNICO | L17: 1 | N17: RADIOLOGIA | O17: DIAGNOSR | P17: DIAGNOSR - CENTRO DEL DIAGNOSTICO | Q17: NO | R17: NNM | S17: 340916 | T17: RADIOGRAFIA PANORAMICA DE CADE | U17: SIN REGION | V17: 1 | W17: ZOTELO, YANINA | X17: 0 | Y17: VARELA, JULIO | Z17: 0 | AA17: 0 | AB17: 0 | AC17: 0 | AD17: S/S | AE17: ELUCERO | AG17: 0 | AH17: 0.3625 | AI17: 46148
A18: 995681 | B18: 46144 | C18: CORIA, ROSA CARMEN | D18: 72 | E18: M | F18: PAMI AMB CC | G18: 150636291101/00 | I18: Lista para Facturar | J18: Exento | K18: IMAGEN SALUD | L18: 2 | N18: DENSITOMETRIA | O18: DIAGNOSR | P18: DIAGNOSR - CENTRO DEL DIAGNOSTICO | Q18: NO | R18: NNM | S18: 341202 | T18: DENSITOMETRIA OSEA DOS O MAS R | U18: SIN REGION | V18: 1 | W18: VEIGA, SABRINA | X18: 0 | Y18: OBLITAS, ROCIO | Z18: 0 | AA18: 0 | AB18: 0 | AC18: 0 | AD18: S/S | AE18: ESLUCERO | AG18: 0 | AH18: 0.36319444 | AI18: 46148
A19: 995682 | B19: 46144 | C19: RIBOTTA, RAUL | D19: 81 | E19: M | F19: PAMI AMB CC | G19: 150501234707/00 | I19: Lista para Facturar | J19: Exento | K19: UNICO | L19: 1 | N19: RADIOLOGIA | O19: DIAGNOSR | P19: DIAGNOSR - CENTRO DEL DIAGNOSTICO | Q19: NO | R19: NNM | S19: 340213 | T19: RX CODO MANO PIE 2 X/PLACA 1EX | U19: SIN REGION | V19: 4 | W19: CARLEVARIS, LEANDRO | X19: 0 | Y19: VARELA, JULIO | Z19: 0 | AA19: 0 | AB19: 0 | AC19: 0 | AD19: S/S | AE19: ESLUCERO | AG19: 0 | AH19: 0.37083333 | AI19: 46148
A20: 995682 | B20: 46144 | C20: RIBOTTA, RAUL | D20: 81 | E20: M | F20: PAMI AMB CC | G20: 150501234707/00 | I20: Lista para Facturar | J20: Exento | K20: UNICO | L20: 1 | N20: RADIOLOGIA | O20: DIAGNOSR | P20: DIAGNOSR - CENTRO DEL DIAGNOSTICO | Q20: NO | R20: NNM | S20: 340209 | T20: RX RAQUIS-COLUMNA- 1 EXP. | U20: SIN REGION | V20: 1 | W20: CARLEVARIS, LEANDRO | X20: 0 | Y20: VARELA, JULIO | Z20: 0 | AA20: 0 | AB20: 0 | AC20: 0 | AD20: S/S | AE20: ESLUCERO | AG20: 0 | AH20: 0.37083333 | AI20: 46148
A21: 995682 | B21: 46144 | C21: RIBOTTA, RAUL | D21: 81 | E21: M | F21: PAMI AMB CC | G21: 150501234707/00 | I21: Lista para Facturar | J21: Exento | K21: UNICO | L21: 1 | N21: RADIOLOGIA | O21: DIAGNOSR | P21: DIAGNOSR - CENTRO DEL DIAGNOSTICO | Q21: NO | R21: NNM | S21: 340210 | T21: RX RAQUIS-COLUMNA-EXP. SUBS. | U21: SIN REGION | V21: 1 | W21: CARLEVARIS, LEANDRO | X21: 0 | Y21: VARELA, JULIO | Z21: 0 | AA21: 0 | AB21: 0 | AC21: 0 | AD21: S/S | AE21: ESLUCERO | AG21: 0 | AH21: 0.37083333 | AI21: 46148
A22: 995682 | B22: 46144 | C22: RIBOTTA, RAUL | D22: 81 | E22: M | F22: PAMI AMB CC | G22: 150501234707/00 | I22: Lista para Facturar | J22: Exento | K22: UNICO | L22: 1 | N22: RADIOLOGIA | O22: DIAGNOSR | P22: DIAGNOSR - CENTRO DEL DIAGNOSTICO | Q22: NO | R22: NNM | S22: 340211 | T22: RX HOMBRO HUMERO PELVIS CADERA | U22: SIN REGION | V22: 1 | W22: CARLEVARIS, LEANDRO | X22: 0 | Y22: VARELA, JULIO | Z22: 0 | AA22: 0 | AB22: 0 | AC22: 0 | AD22: S/S | AE22: ESLUCERO | AG22: 0 | AH22: 0.37083333 | AI22: 46148
A23: 995683 | B23: 46144 | C23: ZELADA, FELIPA | D23: 81 | E23: F | F23: PAMI AMB CC | G23: 150292767108/00 | I23: Lista para Facturar | J23: Exento | K23: UNICO | L23: 1 | N23: TOMOGRAFIA | O23: DIAGNOSR | P23: DIAGNOSR - CENTRO DEL DIAGNOSTICO | Q23: NO | R23: NNM | S23: 341018 | T23: TOMOGRAFIA AXIAL COMPUTADA DE | U23: ABDOMEN | V23: 1 | W23: GERARDI, FRANCISCO JAVIER | X23: 0 | Y23: ASIGNADO, POR RIS | Z23: 0 | AA23: 0 | AB23: 0 | AC23: 0 | AD23: S/S | AE23: ELUCERO | AG23: 0 | AH23: 0.38125 | AI23: 46148
... A27: 995686 | B27: 46144 | C27: DIAZ, EVA ESTELA | D27: 74 | E27: F | F27: PAMI AMB CC | G27: 150634893205/00 | I27: Lista para Facturar | J27: Exento | K27: UNICO | L27: 1 | N27: RADIOLOGIA | O27: DIAGNOSR | P27: MALARG - MALARGUE | Q27: NO | R27: NNM | S27: 340302 | T27: RX TORAX EXP. SUBS. | U27: SIN REGION | V27: 1 | W27: SEPUR, PEDRO MARTIN | X27: 0 | Y27: VARELA, JULIO | Z27: 0 | AA27: 0 | AB27: 0 | AC27: 0 | AD27: S/S | AE27: LOJEDA | AG27: 0 | AH27: 0.38611111 | AI27: 46148
A28: 995687 | B28: 46144 | C28: BARDARO, NICOLAS | D28: 13 | E28: M | F28: MEDIFE | G28: 30665069803000 | I28: Lista para Facturar | J28: Exento | K28: CMSR CD RX-TAC 61037/0 | L28: 1 | N28: RADIOLOGIA | O28: DIAGNOSR | P28: DIAGNOSR - CENTRO DEL DIAGNOSTICO | Q28: NO | R28: NNM | S28: 340301 | T28: RX DE TORAX | U28: SIN REGION | V28: 1 | W28: TROYANO, RICARDO | X28: 0 | Y28: VARELA, JULIO | Z28: 0 | AA28: 0 | AB28: 0 | AC28: 0 | AD28: S/S | AE28: ESLUCERO | AG28: 0 | AH28: 0.38402778 | AI28: 46148
A29: 995687 | B29: 46144 | C29: BARDARO, NICOLAS | D29: 13 | E29: M | F29: MEDIFE | G29: 30665069803000 | I29: Lista para Facturar | J29: Exento | K29: CMSR CD RX-TAC 61037/0 | L29: 1 | N29: RADIOLOGIA | O29: DIAGNOSR | P29: DIAGNOSR - CENTRO DEL DIAGNOSTICO | Q29: NO | R29: NNM | S29: 340302 | T29: RX TORAX EXP. SUBS. | U29: SIN REGION | V29: 1 | W29: TROYANO, RICARDO | X29: 0 | Y29: VARELA, JULIO | Z29: 0 | AA29: 0 | AB29: 0 | AC29: 0 | AD29: S/S | AE29: ESLUCERO | AG29: 0 | AH29: 0.38402778 | AI29: 46148
A30: 995688 | B30: 46144 | C30: CATALAN, APOLINARIO | D30: 78 | E30: M | F30: PAMI AMB CC | G30: 150580886607/00 | I30: Lista para Facturar | J30: Exento | K30: UNICO | L30: 1 | N30: RADIOLOGIA | O30: DIAGNOSR | P30: MALARG - MALARGUE | Q30: NO | R30: NNM | S30: 340211 | T30: RX HOMBRO HUMERO PELVIS CADERA | U30: SIN REGION | V30: 1 | W30: SEPUR, PEDRO MARTIN | X30: 0 | Y30: VARELA, JULIO | Z30: 0 | AA30: 0 | AB30: 0 | AC30: 0 | AD30: S/S | AE30: LOJEDA | AG30: 0 | AH30: 0.3875 | AI30: 46148
A31: 995689 | B31: 46144 | C31: RUIZ, CLAUDIA CRISTINA | D31: 59 | E31: F | F31: PAMI AMB CC | G31: 150927518608/01 | I31: Lista para Facturar | J31: Exento | K31: UNICO | L31: 1 | N31: RADIOLOGIA | O31: DIAGNOSR | P31: DIAGNOSR - CENTRO DEL DIAGNOSTICO | Q31: NO | R31: NNM | S31: 340213 | T31: RX CODO MANO PIE 2 X/PLACA 1EX | U31: SIN REGION | V31: 2 | W31: GERARDI, FRANCISCO JAVIER | X31: 0 | Y31: VARELA, JULIO | Z31: 0 | AA31: 0 | AB31: 0 | AC31: 0 | AD31: S/S | AE31: ELUCERO | AG31: 0 | AH31: 0.38819444 | AI31: 46148
A32: 995690 | B32: 46144 | C32: BENEDETTO, CARLOS ALBERTO | D32: 74 | E32: M | F32: PAMI AMB CC | G32: 150631767202/00 | I32: Lista para Facturar | J32: Exento | K32: UNICO | L32: 1 | N32: RADIOLOGIA | O32: DIAGNOSR | P32: MALARG - MALARGUE | Q32: NO | R32: NNM | S32: 340209 | T32: RX RAQUIS-COLUMNA- 1 EXP. | U32: SIN REGION | V32: 1 | W32: SEPUR, PEDRO MARTIN | X32: 0 | Y32: VARELA, JULIO | Z32: 0 | AA32: 0 | AB32: 0 | AC32: 0 | AD32: S/S | AE32: LOJEDA | AG32: 0 | AH32: 0.38819444 | AI32: 46148
A33: 995690 | B33: 46144 | C33: BENEDETTO, CARLOS ALBERTO | D33: 74 | E33: M | F33: PAMI AMB CC | G33: 150631767202/00 | I33: Lista para Facturar | J33: Exento | K33: UNICO | L33: 1 | N33: RADIOLOGIA | O33: DIAGNOSR | P33: MALARG - MALARGUE | Q33: NO | R33: NNM | S33: 340210 | T33: RX RAQUIS-COLUMNA-EXP. SUBS. | U33: SIN REGION | V33: 1 | W33: SEPUR, PEDRO MARTIN | X33: 0 | Y33: VARELA, JULIO | Z33: 0 | AA33: 0 | AB33: 0 | AC33: 0 | AD33: S/S | AE33: LOJEDA | AG33: 0 | AH33: 0.38819444 | AI33: 46148
A34: 995691 | B34: 46144 | C34: CARA, MARIA HORTENCIA | D34: 51 | E34: F | F34: H REGIONAL MG | G34: 24169379 | I34: Lista para Facturar | J34: Exento | K34: UNICO | L34: 1 | N34: TOMOGRAFIA | O34: DIAGNOSR | P34: MALARG - MALARGUE | Q34: NO | R34: NNM | S34: 922026 | T34: TOMOGRAFIA COMPUTADA MULTICORT | U34: SIN REGION | V34: 1 | W34: GIORDANINI, SERGIO | X34: 0 | Y34: ASIGNADO, POR RIS | Z34: 0 | AA34: 0 | AB34: 0 | AC34: 0 | AD34: S/S | AE34: CIRIARTE | AG34: 0 | AH34: 0.38819444 | AI34: 46148
A35: 995692 | B35: 46144 | C35: HEREDIA, MARIA LEONOR | D35: 73 | E35: M | F35: PAMI AMB CC | G35: 115341247848/00 | I35: Lista para Facturar | J35: Exento | K35: UNICO | L35: 1 | N35: TOMOGRAFIA | O35: DIAGNOSR | P35: DIAGNOSR - CENTRO DEL DIAGNOSTICO | Q35: NO | R35: NNM | S35: 341008 | T35: TOMOGRAFIA COMPUTADA ABDOMINAL | U35: ABD. Y PELVIS | V35: 1 | W35: PEREZ, JOSE LUIS | X35: 0 | Y35: ASIGNADO, POR RIS | Z35: 0 | AA35: 0 | AB35: 0 | AC35: 0 | AD35: S/S | AE35: ESLUCERO | AG35: 0 | AH35: 0.38888889 | AI35: 46148
A36: 995693 | B36: 46144 | C36: PERE, HAYDEE | D36: 66 | E36: F | F36: PAMI AMB CC | G36: 155075039707/00 | I36: Lista para Facturar | J36: Exento | K36: IMAGEN SALUD | L36: 2 | N36: DENSITOMETRIA | O36: DIAGNOSR | P36: DIAGNOSR - CENTRO DEL DIAGNOSTICO | Q36: NO | R36: NNM | S36: 341202 | T36: DENSITOMETRIA OSEA DOS O MAS R | U36: SIN REGION | V36: 1 | W36: CARLEVARIS, LEANDRO | X36: 0 | Y36: OBLITAS, ROCIO | Z36: 0 | AA36: 0 | AB36: 0 | AC36: 0 | AD36: S/S | AE36: ELUCERO | AG36: 0 | AH36: 0.39166667 | AI36: 46148
A37: 995694 | B37: 46144 | C37: CAIAZZA REIA, ANIELLO | D37: 75 | E37: M | F37: PAMI AMB CC | G37: 150992887508/00 | I37: Lista para Facturar | J37: Exento | K37: UNICO | L37: 1 | N37: RADIOLOGIA | O37: DIAGNOSR | P37: DIAGNOSR - CENTRO DEL DIAGNOSTICO | Q37: NO | R37: NNM | S37: 340214 | T37: MED. COMPARATIVA DE M.I.XESTUD | U37: SIN REGION | V37: 1 | W37: LUFFI, MARIA YAMILA | X37: 0 | Y37: VARELA, JULIO | Z37: 0 | AA37: 0 | AB37: 0 | AC37: 0 | AD37: S/S | AE37: ELUCERO | AG37: 0 | AH37: 0.39375 | AI37: 46148
A38: 995695 | B38: 46144 | C38: MADARIETA, CARMEN RAQUEL | D38: 78 | E38: F | F38: PAMI AMB CC | G38: 150391498709/00 | I38: Lista para Facturar | J38: Exento | K38: IMAGEN SALUD | L38: 2 | N38: DENSITOMETRIA | O38: DIAGNOSR | P38: DIAGNOSR - CENTRO DEL DIAGNOSTICO | Q38: NO | R38: NNM | S38: 341202 | T38: DENSITOMETRIA OSEA DOS O MAS R | U38: SIN REGION | V38: 1 | W38: OBLITAS, ROCIO | X38: 0 | Y38: OBLITAS, ROCIO | Z38: 0 | AA38: 0 | AB38: 0 | AC38: 0 | AD38: S/S | AE38: ELUCERO | AG38: 0 | AH38: 0.39583333 | AI38: 46148
A39: 995696 | B39: 46144 | C39: VILLAR, IRMA NELIDA | D39: 72 | E39: F | F39: PAMI AMB CC | G39: 150634924604/00 | I39: Lista para Facturar | J39: Exento | K39: UNICO | L39: 1 | N39: RADIOLOGIA | O39: DIAGNOSR | P39: MALARG - MALARGUE | Q39: NO | R39: NNM | S39: 340209 | T39: RX RAQUIS-COLUMNA- 1 EXP. | U39: SIN REGION | V39: 1 | W39: SEPUR, PEDRO MARTIN | X39: 0 | Y39: VARELA, JULIO | Z39: 0 | AA39: 0 | AB39: 0 | AC39: 0 | AD39: S/S | AE39: LOJEDA | AG39: 0 | AH39: 0.39583333 | AI39: 46148
A40: 995696 | B40: 46144 | C40: VILLAR, IRMA NELIDA | D40: 72 | E40: F | F40: PAMI AMB CC | G40: 150634924604/00 | I40: Lista para Facturar | J40: Exento | K40: UNICO | L40: 1 | N40: RADIOLOGIA | O40: DIAGNOSR | P40: MALARG - MALARGUE | Q40: NO | R40: NNM | S40: 340210 | T40: RX RAQUIS-COLUMNA-EXP. SUBS. | U40: SIN REGION | V40: 1 | W40: SEPUR, PEDRO MARTIN | X40: 0 | Y40: VARELA, JULIO | Z40: 0 | AA40: 0 | AB40: 0 | AC40: 0 | AD40: S/S | AE40: LOJEDA | AG40: 0 | AH40: 0.39583333 | AI40: 46148
A41: 995696 | B41: 46144 | C41: VILLAR, IRMA NELIDA | D41: 72 | E41: F | F41: PAMI AMB CC | G41: 150634924604/00 | I41: Lista para Facturar | J41: Exento | K41: UNICO | L41: 1 | N41: RADIOLOGIA | O41: DIAGNOSR | P41: MALARG - MALARGUE | Q41: NO | R41: NNM | S41: 340211 | T41: RX HOMBRO HUMERO PELVIS CADERA | U41: SIN REGION | V41: 2 | W41: SEPUR, PEDRO MARTIN | X41: 0 | Y41: VARELA, JULIO | Z41: 0 | AA41: 0 | AB41: 0 | AC41: 0 | AD41: S/S | AE41: LOJEDA | AG41: 0 | AH41: 0.39583333 | AI41: 46148
A42: 995696 | B42: 46144 | C42: VILLAR, IRMA NELIDA | D42: 72 | E42: F | F42: PAMI AMB CC | G42: 150634924604/00 | I42: Lista para Facturar | J42: Exento | K42: UNICO | L42: 1 | N42: RADIOLOGIA | O42: DIAGNOSR | P42: MALARG - MALARGUE | Q42: NO | R42: NNM | S42: 340212 | T42: POR EXPOSICION SUBSIGUIENTE | U42: SIN REGION | V42: 1 | W42: SEPUR, PEDRO MARTIN | X42: 0 | Y42: VARELA, JULIO | Z42: 0 | AA42: 0 | AB42: 0 | AC42: 0 | AD42: S/S | AE42: LOJEDA | AG42: 0 | AH42: 0.39583333 | AI42: 46148
A43: 995696 | B43: 46144 | C43: VILLAR, IRMA NELIDA | D43: 72 | E43: F | F43: PAMI AMB CC | G43: 150634924604/00 | I43: Lista para Facturar | J43: Exento | K43: UNICO | L43: 1 | N43: RADIOLOGIA | O43: DIAGNOSR | P43: MALARG - MALARGUE | Q43: NO | R43: NNM | S43: 340213 | T43: RX CODO MANO PIE 2 X/PLACA 1EX | U43: SIN REGION | V43: 2 | W43: SEPUR, PEDRO MARTIN | X43: 0 | Y43: VARELA, JULIO | Z43: 0 | AA43: 0 | AB43: 0 | AC43: 0 | AD43: S/S | AE43: LOJEDA | AG43: 0 | AH43: 0.39583333 | AI43: 46148
...

Sheet DERIVANTES
A1: ID | B1: DERIVANTE | C1: MAT | D1: PROPIO/EXTERNO | E1: PISO | F1: SIN ESPACIOS
A2: 5 | B2: SCHIAVONE, JULIO | C2: 11079 | D2: =IF(B2="","",IFERROR(VLOOKUP(B2,'DERIVANTES PROPIOS'!A:D,2,FALSE),"RESTO")) -> RESTO | E2: =IF(B2="","",IFERROR(VLOOKUP(B2,'DERIVANTES PROPIOS'!A:D,3,FALSE),"RESTO")) -> RESTO | F2: =+TRIM(B2) -> SCHIAVONE, JULIO
A3: 6 | B3: CERRUTI, FAUSTO | C3: 8285 | D3: =IF(B3="","",IFERROR(VLOOKUP(B3,'DERIVANTES PROPIOS'!A:D,2,FALSE),"RESTO")) -> RESTO | E3: =IF(B3="","",IFERROR(VLOOKUP(B3,'DERIVANTES PROPIOS'!A:D,3,FALSE),"RESTO")) -> RESTO | F3: =+TRIM(B3) -> CERRUTI, FAUSTO
A4: 8 | B4: SCHIAVONE, LEONARDO | C4: 11080 | D4: =IF(B4="","",IFERROR(VLOOKUP(B4,'DERIVANTES PROPIOS'!A:D,2,FALSE),"RESTO")) -> RESTO | E4: =IF(B4="","",IFERROR(VLOOKUP(B4,'DERIVANTES PROPIOS'!A:D,3,FALSE),"RESTO")) -> RESTO | F4: =+TRIM(B4) -> SCHIAVONE, LEONARDO
A5: 9 | B5: CASADO, HEBE SILVINA | C5: 8203 | D5: =IF(B5="","",IFERROR(VLOOKUP(B5,'DERIVANTES PROPIOS'!A:D,2,FALSE),"RESTO")) -> RESTO | E5: =IF(B5="","",IFERROR(VLOOKUP(B5,'DERIVANTES PROPIOS'!A:D,3,FALSE),"RESTO")) -> RESTO | F5: =+TRIM(B5) -> CASADO, HEBE SILVINA
A6: 10 | B6: GOMILA, JORGE | C6: 9149 | D6: =IF(B6="","",IFERROR(VLOOKUP(B6,'DERIVANTES PROPIOS'!A:D,2,FALSE),"RESTO")) -> RESTO | E6: =IF(B6="","",IFERROR(VLOOKUP(B6,'DERIVANTES PROPIOS'!A:D,3,FALSE),"RESTO")) -> RESTO | F6: =+TRIM(B6) -> GOMILA, JORGE
A7: 11 | B7: NOMI, MARIA DEL CARMEN | C7: 10188 | D7: =IF(B7="","",IFERROR(VLOOKUP(B7,'DERIVANTES PROPIOS'!A:D,2,FALSE),"RESTO")) -> RESTO | E7: =IF(B7="","",IFERROR(VLOOKUP(B7,'DERIVANTES PROPIOS'!A:D,3,FALSE),"RESTO")) -> RESTO | F7: =+TRIM(B7) -> NOMI, MARIA DEL CARMEN
A8: 12 | B8: BOROVINA, ALDO | C8: 7996 | D8: =IF(B8="","",IFERROR(VLOOKUP(B8,'DERIVANTES PROPIOS'!A:D,2,FALSE),"RESTO")) -> RESTO | E8: =IF(B8="","",IFERROR(VLOOKUP(B8,'DERIVANTES PROPIOS'!A:D,3,FALSE),"RESTO")) -> RESTO | F8: =+TRIM(B8) -> BOROVINA, ALDO
A9: 13 | B9: MUDCHELLA, OSCAR | C9: 10063 | D9: =IF(B9="","",IFERROR(VLOOKUP(B9,'DERIVANTES PROPIOS'!A:D,2,FALSE),"RESTO")) -> RESTO | E9: =IF(B9="","",IFERROR(VLOOKUP(B9,'DERIVANTES PROPIOS'!A:D,3,FALSE),"RESTO")) -> RESTO | F9: =+TRIM(B9) -> MUDCHELLA, OSCAR
A10: 14 | B10: FRANCISCO, MARIA | C10: 8875 | D10: =IF(B10="","",IFERROR(VLOOKUP(B10,'DERIVANTES PROPIOS'!A:D,2,FALSE),"RESTO")) -> RESTO | E10: =IF(B10="","",IFERROR(VLOOKUP(B10,'DERIVANTES PROPIOS'!A:D,3,FALSE),"RESTO")) -> RESTO | F10: =+TRIM(B10) -> FRANCISCO, MARIA
A11: 15 | B11: PEREZ, ROBERTO | C11: 10431 | D11: =IF(B11="","",IFERROR(VLOOKUP(B11,'DERIVANTES PROPIOS'!A:D,2,FALSE),"RESTO")) -> RESTO | E11: =IF(B11="","",IFERROR(VLOOKUP(B11,'DERIVANTES PROPIOS'!A:D,3,FALSE),"RESTO")) -> RESTO | F11: =+TRIM(B11) -> PEREZ, ROBERTO
A12: 16 | B12: BOROVINA, ANA | C12: 7997 | D12: =IF(B12="","",IFERROR(VLOOKUP(B12,'DERIVANTES PROPIOS'!A:D,2,FALSE),"RESTO")) -> RESTO | E12: =IF(B12="","",IFERROR(VLOOKUP(B12,'DERIVANTES PROPIOS'!A:D,3,FALSE),"RESTO")) -> RESTO | F12: =+TRIM(B12) -> BOROVINA, ANA
A13: 17 | B13: CERRUTI, JUAN CARLOS | C13: 8286 | D13: =IF(B13="","",IFERROR(VLOOKUP(B13,'DERIVANTES PROPIOS'!A:D,2,FALSE),"RESTO")) -> RESTO | E13: =IF(B13="","",IFERROR(VLOOKUP(B13,'DERIVANTES PROPIOS'!A:D,3,FALSE),"RESTO")) -> RESTO | F13: =+TRIM(B13) -> CERRUTI, JUAN CARLOS
... A4271: 4338 | B4271: MARCELO, JORGE | C4271: 1658 | D4271: =IF(B4271="","",IFERROR(VLOOKUP(B4271,'DERIVANTES PROPIOS'!A:D,2,FALSE),"RESTO")) -> RESTO | E4271: =IF(B4271="","",IFERROR(VLOOKUP(B4271,'DERIVANTES PROPIOS'!A:D,3,FALSE),"RESTO")) -> RESTO | F4271: =+TRIM(B4271) -> MARCELO, JORGE

Sheet DERIVANTES PROPIOS
A1: APELLIDO NOMBRE | B1: PROPIO/EXTERNO | C1: PISO
A2: BITTAR GARCIA, CARLOS | B2: PROPIO | C2: PISO1
A3: BLANCO ALLEMANT, ALEJANDRA | B3: PROPIO | C3: PISO1
A4: CABAÑA, R JAVIER | B4: PROPIO | C4: PISO1
A5: CRUZ PEREZ, INES | B5: PROPIO | C5: PISO1
A6: FORNARA, CRISTIAN | B6: PROPIO | C6: PISO1
A7: GERARDI, FRANCISCO JAVIER | B7: PROPIO | C7: PISO1
A8: MARTINEZ, ANTONELLA | B8: PROPIO | C8: PISO1
A9: ANTONINI, GUSTAVO | B9: PROPIO | C9: PISO2
A10: CAMILLETTI, MARIANO | B10: PROPIO | C10: PISO2
A11: CARLEVARIS, LEANDRO | B11: PROPIO | C11: PISO2
A12: CHAVARRI, EDUARDO | B12: PROPIO | C12: PISO2
... A39: SIN PEDIDO MEDICO, . | B39: SIN PEDIDO MEDICO | C39: RESTO

Sheet SERVICIOS
A1: DENSITOMETRIA
A2: ECO DOPPLER COLOR
A3: ECOCARDIOGRAMA
A4: ECOGRAFIA
A5: ELECTROCARDIOGRAMA
A6: MAMOGRAFIA
A7: ODONTOLOGIA-2D
A8: ODONTOLOGIA-3D
A9: RADIOLOGIA
A10: RESONANCIA
A11: TOMOGRAFIA
